<mujoco model="go2 scene">
  <compiler angle="radian" meshdir="dae" autolimits="true"/>
  
  <option timestep="0.002" iterations="50" solver="Newton" gravity="0 0 -9.81"/>

  <default>
    <geom contype="1" conaffinity="1" condim="3" friction="0.9 0.005 0.0001" rgba="0.8 0.6 0.4 1.0" margin="0.001"/>
    <joint damping="0.5" armature="0.01"/>
    <motor ctrllimited="true" ctrlrange="-33.5 33.5"/>
  </default>

  <asset>
    <mesh name="base" file="base.dae"/>
    <mesh name="hip" file="hip.dae"/>
    <mesh name="thigh" file="thigh.dae"/>
    <mesh name="thigh_mirror" file="thigh_mirror.dae"/>
    <mesh name="calf" file="calf.dae"/>
    <mesh name="calf_mirror" file="calf_mirror.dae"/>
    <mesh name="foot" file="foot.dae"/>
    <texture type="skybox" builtin="flat" rgb1="0 0 0" rgb2="0 0 0" width="512" height="3072"/>
    <texture type="2d" name="groundplane" builtin="checker" mark="edge" rgb1="0.2 0.3 0.4" rgb2="0.1 0.2 0.3" markrgb="0.8 0.8 0.8" width="300" height="300"/>
    <material name="groundplane" texture="groundplane" texuniform="true" texrepeat="5 5" reflectance="0.2"/>
  </asset>

  <worldbody>
    <light pos="0 0 3.5" dir="0 0 -1" directional="true"/>
    <geom name="floor" size="0 0 0.05" type="plane" material="groundplane"/>
    
    <!-- Go2 Robot -->
    <body name="base" pos="0 0 0.42">
      <inertial pos="0.021112 0 -0.005366" mass="6.921" 
                diaginertia="0.107 0.098077 0.02448"/>
      <geom type="box" size="0.1881 0.04675 0.057" rgba="0.7 0.7 0.7 1"/>
      <freejoint/>
      
      <!-- Front Left Leg -->
      <body name="FL_hip" pos="0.1934 0.0465 0">
        <inertial pos="-0.0054 0.00194 -0.000105" mass="0.678" 
                  diaginertia="0.000596 0.000884 0.00048"/>
        <joint name="FL_hip_joint" type="hinge" axis="1 0 0" range="-1.0472 1.0472" damping="0.5"/>
        <geom type="cylinder" size="0.046 0.02" pos="0 0.08 0" quat="0.707 0.707 0 0" rgba="0.5 0.5 0.5 1"/>
        
        <body name="FL_thigh" pos="0 0.0955 0">
          <inertial pos="-0.00374 -0.0223 -0.0327" mass="1.152" 
                    diaginertia="0.00103 0.0058 0.00584"/>
          <joint name="FL_thigh_joint" type="hinge" axis="0 1 0" range="-1.5708 3.4907" damping="0.5"/>
          <geom type="box" size="0.055 0.01225 0.017" pos="0 0 -0.1065" quat="0.707 0 0.707 0" rgba="0.6 0.6 0.6 1"/>
          
          <body name="FL_calf" pos="0 0 -0.213">
            <inertial pos="0.00548 -0.000975 -0.115" mass="0.154" 
                      diaginertia="3.29e-05 0.0011 0.00108"/>
            <joint name="FL_calf_joint" type="hinge" axis="0 1 0" range="-2.7227 -0.83776" damping="0.5"/>
            <geom type="cylinder" size="0.012 0.06" pos="0.008 0 -0.06" quat="0.995 0 0.105 0" rgba="0.5 0.5 0.5 1"/>
            
            <body name="FL_foot" pos="0 0 -0.213">
              <inertial pos="0 0 0" mass="0.04" diaginertia="9.6e-06 9.6e-06 9.6e-06"/>
              <geom name="FL_foot" type="sphere" size="0.022" pos="-0.002 0 0" rgba="0.3 0.3 0.3 1"/>
            </body>
          </body>
        </body>
      </body>
      
      <!-- Front Right Leg -->
      <body name="FR_hip" pos="0.1934 -0.0465 0">
        <inertial pos="-0.0054 -0.00194 -0.000105" mass="0.678" 
                  diaginertia="0.000596 0.000884 0.00048"/>
        <joint name="FR_hip_joint" type="hinge" axis="1 0 0" range="-1.0472 1.0472" damping="0.5"/>
        <geom type="cylinder" size="0.046 0.02" pos="0 -0.08 0" quat="0.707 0.707 0 0" rgba="0.5 0.5 0.5 1"/>
        
        <body name="FR_thigh" pos="0 -0.0955 0">
          <inertial pos="-0.00374 0.0223 -0.0327" mass="1.152" 
                    diaginertia="0.00103 0.0058 0.00584"/>
          <joint name="FR_thigh_joint" type="hinge" axis="0 1 0" range="-1.5708 3.4907" damping="0.5"/>
          <geom type="box" size="0.055 0.01225 0.017" pos="0 0 -0.1065" quat="0.707 0 0.707 0" rgba="0.6 0.6 0.6 1"/>
          
          <body name="FR_calf" pos="0 0 -0.213">
            <inertial pos="0.00548 0.000975 -0.115" mass="0.154" 
                      diaginertia="3.29e-05 0.0011 0.00108"/>
            <joint name="FR_calf_joint" type="hinge" axis="0 1 0" range="-2.7227 -0.83776" damping="0.5"/>
            <geom type="cylinder" size="0.013 0.06" pos="0.01 0 -0.06" quat="0.998 0 0.063 0" rgba="0.5 0.5 0.5 1"/>
            
            <body name="FR_foot" pos="0 0 -0.213">
              <inertial pos="0 0 0" mass="0.04" diaginertia="9.6e-06 9.6e-06 9.6e-06"/>
              <geom name="FR_foot" type="sphere" size="0.022" pos="-0.002 0 0" rgba="0.3 0.3 0.3 1"/>
            </body>
          </body>
        </body>
      </body>
      
      <!-- Rear Left Leg -->
      <body name="RL_hip" pos="-0.1934 0.0465 0">
        <inertial pos="0.0054 0.00194 -0.000105" mass="0.678" 
                  diaginertia="0.000596 0.000884 0.00048"/>
        <joint name="RL_hip_joint" type="hinge" axis="1 0 0" range="-1.0472 1.0472" damping="0.5"/>
        <geom type="cylinder" size="0.046 0.02" pos="0 0.08 0" quat="0.707 0.707 0 0" rgba="0.5 0.5 0.5 1"/>
        
        <body name="RL_thigh" pos="0 0.0955 0">
          <inertial pos="-0.00374 -0.0223 -0.0327" mass="1.152" 
                    diaginertia="0.00103 0.0058 0.00584"/>
          <joint name="RL_thigh_joint" type="hinge" axis="0 1 0" range="-0.5236 4.5379" damping="0.5"/>
          <geom type="box" size="0.055 0.01225 0.017" pos="0 0 -0.1065" quat="0.707 0 0.707 0" rgba="0.6 0.6 0.6 1"/>
          
          <body name="RL_calf" pos="0 0 -0.213">
            <inertial pos="0.00548 -0.000975 -0.115" mass="0.154" 
                      diaginertia="3.29e-05 0.0011 0.00108"/>
            <joint name="RL_calf_joint" type="hinge" axis="0 1 0" range="-2.7227 -0.83776" damping="0.5"/>
            <geom type="cylinder" size="0.013 0.06" pos="0.01 0 -0.06" quat="0.998 0 0.063 0" rgba="0.5 0.5 0.5 1"/>
            
            <body name="RL_foot" pos="0 0 -0.213">
              <inertial pos="0 0 0" mass="0.04" diaginertia="9.6e-06 9.6e-06 9.6e-06"/>
              <geom name="RL_foot" type="sphere" size="0.022" pos="-0.002 0 0" rgba="0.3 0.3 0.3 1"/>
            </body>
          </body>
        </body>
      </body>
      
      <!-- Rear Right Leg -->
      <body name="RR_hip" pos="-0.1934 -0.0465 0">
        <inertial pos="0.0054 -0.00194 -0.000105" mass="0.678" 
                  diaginertia="0.000596 0.000884 0.00048"/>
        <joint name="RR_hip_joint" type="hinge" axis="1 0 0" range="-1.0472 1.0472" damping="0.5"/>
        <geom type="cylinder" size="0.046 0.02" pos="0 -0.08 0" quat="0.707 0.707 0 0" rgba="0.5 0.5 0.5 1"/>
        
        <body name="RR_thigh" pos="0 -0.0955 0">
          <inertial pos="-0.00374 0.0223 -0.0327" mass="1.152" 
                    diaginertia="0.00103 0.0058 0.00584"/>
          <joint name="RR_thigh_joint" type="hinge" axis="0 1 0" range="-0.5236 4.5379" damping="0.5"/>
          <geom type="box" size="0.055 0.01225 0.017" pos="0 0 -0.1065" quat="0.707 0 0.707 0" rgba="0.6 0.6 0.6 1"/>
          
          <body name="RR_calf" pos="0 0 -0.213">
            <inertial pos="0.00548 0.000975 -0.115" mass="0.154" 
                      diaginertia="3.29e-05 0.0011 0.00108"/>
            <joint name="RR_calf_joint" type="hinge" axis="0 1 0" range="-2.7227 -0.83776" damping="0.5"/>
            <geom type="cylinder" size="0.013 0.06" pos="0.01 0 -0.06" quat="0.998 0 0.063 0" rgba="0.5 0.5 0.5 1"/>
            
            <body name="RR_foot" pos="0 0 -0.213">
              <inertial pos="0 0 0" mass="0.04" diaginertia="9.6e-06 9.6e-06 9.6e-06"/>
              <geom name="RR_foot" type="sphere" size="0.022" pos="-0.002 0 0" rgba="0.3 0.3 0.3 1"/>
            </body>
          </body>
        </body>
      </body>
      
    </body>
  </worldbody>
  
  <actuator>
    <motor name="FL_hip" joint="FL_hip_joint" gear="1" ctrllimited="true" ctrlrange="-23.7 23.7"/>
    <motor name="FL_thigh" joint="FL_thigh_joint" gear="1" ctrllimited="true" ctrlrange="-23.7 23.7"/>
    <motor name="FL_calf" joint="FL_calf_joint" gear="1" ctrllimited="true" ctrlrange="-35.55 35.55"/>
    
    <motor name="FR_hip" joint="FR_hip_joint" gear="1" ctrllimited="true" ctrlrange="-23.7 23.7"/>
    <motor name="FR_thigh" joint="FR_thigh_joint" gear="1" ctrllimited="true" ctrlrange="-23.7 23.7"/>
    <motor name="FR_calf" joint="FR_calf_joint" gear="1" ctrllimited="true" ctrlrange="-35.55 35.55"/>
    
    <motor name="RL_hip" joint="RL_hip_joint" gear="1" ctrllimited="true" ctrlrange="-23.7 23.7"/>
    <motor name="RL_thigh" joint="RL_thigh_joint" gear="1" ctrllimited="true" ctrlrange="-23.7 23.7"/>
    <motor name="RL_calf" joint="RL_calf_joint" gear="1" ctrllimited="true" ctrlrange="-35.55 35.55"/>
    
    <motor name="RR_hip" joint="RR_hip_joint" gear="1" ctrllimited="true" ctrlrange="-23.7 23.7"/>
    <motor name="RR_thigh" joint="RR_thigh_joint" gear="1" ctrllimited="true" ctrlrange="-23.7 23.7"/>
    <motor name="RR_calf" joint="RR_calf_joint" gear="1" ctrllimited="true" ctrlrange="-35.55 35.55"/>
  </actuator>
  
</mujoco>

